<?xml version="1.0" ?>
<sdf version="1.5">
    <world name="earth">

        <physics type="ode">
            <max_step_size>0.001</max_step_size>
            <real_time_factor>1</real_time_factor>
            <real_time_update_rate>1000</real_time_update_rate>
            <gravity>0 0 -9.81</gravity>
            <ode>
                <solver>
                <type>quick</type>
                <min_step_size>0.0001</min_step_size>   
                <iters>50</iters> 
                <sor>1.3</sor>
                </solver>  
                <constraints>
                <cfm>0.0</cfm>
                <erp>0.2</erp>
                </constraints>  
            </ode>
        </physics>

        <scene>
            
        </scene>

        <!-- A global light source -->
        <include>
            <uri>model://sun</uri>
        </include>
        
		<!-- 地板 -->
		<model name="ground_plane">

			<static>true</static>
			<link name="link">
				<collision name="collision">
					<geometry>
					<plane>
							<normal>0 0 1</normal>
							<size>100 100</size>
					</plane>
					</geometry>
				<surface>
					<friction>
						<ode>
						<mu>100</mu>
						<mu2>50</mu2>
						</ode>
					</friction>
				</surface>
				</collision>
				<visual name="visual">
					<cast_shadows>false</cast_shadows>
					<geometry>
					<plane>
						<normal>0 0 1</normal>
						<size>100 100</size>
					</plane>
					</geometry>
					<material>
						<ambient>0.22 0.24 0.26 1</ambient>
							<diffuse>0.22 0.24 0.26 1</diffuse>
					</material>
				</visual>
			</link>
		</model>
        
		<!-- 跑道 -->
        <model name='race'>
           	<pose>1.5 5.87 1.18 0 0 -1.57</pose>
      	   	<static>true</static>
           	<link name='1area_border_00'>
           	<pose>0 0 0 0 0 0</pose>
        	<visual name="1area_border_visual">
          		<geometry>
          			<mesh>
              			   <uri>/home/cyberdog_sim/src/cyberdog_simulator/cyberdog_gazebo/model/race2026_meshes/1_border.stl</uri>
              			   <scale>0.01 0.01 0.01</scale>
            			</mesh>	
          		</geometry>
          		<material>
        			<ambient>1 1 0.5 1</ambient>
        			<diffuse>1 1 0.5 1</diffuse>
      			</material>
                </visual>
           	</link>
            
		</model>
		  
			

		
			

		


		

		

		

       
		
		<model name="hanging_ball">
			<link name="base_link"></link>
            <!--第二个区域的蓝色球-->
			<link name='2area_ball'>
			  <pose> 0.95 11.1 0.3 0 0 0</pose>
           	  <collision name="2area_ball_collision">
                  <geometry>
					<sphere>
						<radius>0.1</radius>
					</sphere>			
          		  </geometry>
              </collision>
        	  <visual name="2area_ball_visual">
          		<geometry>
					<sphere>
						<radius>0.1</radius>
					</sphere>			
          		</geometry>
          		<material>
        			<ambient>0.43 0.74 0.93 1</ambient>
        			<diffuse>0.43 0.74 0.93 1</diffuse>
      			</material>
              </visual>
           </link>

			<joint name="2area_ball_joint" type="ball">
				<pose>0 0 0.3 0 0 0</pose>
				<parent>base_link</parent>
				<child>2area_ball</child>
				<dynamics>
        			<damping>0.5</damping> 
      			</dynamics>
    		</joint>

			<!--第二赛段的16个小球-->
			<link name='1area_ball1_1'>
			  <pose> -0.4 1.34 0.3 0 0 0</pose>
           	  <collision name="1area_ball_collision">
                  <geometry>
					<sphere>
						<radius>0.1</radius>
					</sphere>			
          		  </geometry>
              </collision>
        	  <visual name="1area_ball_visual">
          		<geometry>
					<sphere>
						<radius>0.1</radius>
					</sphere>			
          		</geometry>
          		<material>
        			<ambient>0.43 0.74 0.93 1</ambient>
        			<diffuse>0.43 0.74 0.93 1</diffuse>
      			</material>
              </visual>
           </link>

			<joint name="1area_ball1_1_joint" type="ball">
				<pose>0 0 0.3 0 0 0</pose>
				<parent>base_link</parent>
				<child>1area_ball1_1</child>
				<dynamics>
        			<damping>0.5</damping> 
      			</dynamics>
    		</joint>

			<joint name="world_to_base" type="fixed">
      			<parent>world</parent>
      			<child>base_link</child>
      			<pose>0 0 0 0 0 0</pose> 
    		</joint>

			<link name='1area_ball1_2'>
			  <pose> 0.8 1.34 0.3 0 0 0</pose>
           	  <collision name="1area_ball_collision">
                  <geometry>
					<sphere>
						<radius>0.1</radius>
					</sphere>			
          		  </geometry>
              </collision>
        	  <visual name="1area_ball_visual">
          		<geometry>
					<sphere>
						<radius>0.1</radius>
					</sphere>			
          		</geometry>
          		<material>
        			<ambient>0.92 0.45 0.17 1</ambient>
        			<diffuse>0.92 0.45 0.17 1</diffuse>
      			</material>
              </visual>
           </link>

			<joint name="1area_ball1_2_joint" type="ball">
				<pose>0 0 0.3 0 0 0</pose>
				<parent>base_link</parent>
				<child>1area_ball1_2</child>
				<dynamics>
        			<damping>0.5</damping> 
      			</dynamics>
    		</joint>

			<link name='1area_ball1_3'>
			  <pose> 2 1.34 0.3 0 0 0</pose>
           	  <collision name="1area_ball_collision">
                  <geometry>
					<sphere>
						<radius>0.1</radius>
					</sphere>			
          		  </geometry>
              </collision>
        	  <visual name="1area_ball_visual">
          		<geometry>
					<sphere>
						<radius>0.1</radius>
					</sphere>			
          		</geometry>
          		<material>
        			<ambient>0.43 0.74 0.93 1</ambient>
        			<diffuse>0.43 0.74 0.93 1</diffuse>
      			</material>
              </visual>
           </link>

			<joint name="1area_ball1_3_joint" type="ball">
				<pose>0 0 0.3 0 0 0</pose>
				<parent>base_link</parent>
				<child>1area_ball1_3</child>
				<dynamics>
        			<damping>0.5</damping> 
      			</dynamics>
    		</joint>

			<link name='1area_ball1_4'>
			  <pose> 3.2 1.34 0.3 0 0 0</pose>
           	  <collision name="1area_ball_collision">
                  <geometry>
					<sphere>
						<radius>0.1</radius>
					</sphere>			
          		  </geometry>
              </collision>
        	  <visual name="1area_ball_visual">
          		<geometry>
					<sphere>
						<radius>0.1</radius>
					</sphere>			
          		</geometry>
          		<material>
        			<ambient>0.43 0.74 0.93 1</ambient>
        			<diffuse>0.43 0.74 0.93 1</diffuse>
      			</material>
              </visual>
           </link>

			<joint name="1area_ball1_4_joint" type="ball">
				<pose>0 0 0.3 0 0 0</pose>
				<parent>base_link</parent>
				<child>1area_ball1_4</child>
				<dynamics>
        			<damping>0.5</damping> 
      			</dynamics>
    		</joint>

			<link name='1area_ball2_1'>
			  <pose> -0.4 2.18 0.3 0 0 0</pose>
           	  <collision name="1area_ball_collision">
                  <geometry>
					<sphere>
						<radius>0.1</radius>
					</sphere>			
          		  </geometry>
              </collision>
        	  <visual name="1area_ball_visual">
          		<geometry>
					<sphere>
						<radius>0.1</radius>
					</sphere>			
          		</geometry>
          		<material>
        			<ambient>0.43 0.74 0.93 1</ambient>
        			<diffuse>0.43 0.74 0.93 1</diffuse>
      			</material>
              </visual>
           </link>

			<joint name="1area_ball2_1_joint" type="ball">
				<pose>0 0 0.3 0 0 0</pose>
				<parent>base_link</parent>
				<child>1area_ball2_1</child>
				<dynamics>
        			<damping>0.5</damping> 
      			</dynamics>
    		</joint>

			<link name='1area_ball2_2'>
			  <pose> 0.8 2.18 0.3 0 0 0</pose>
           	  <collision name="1area_ball_collision">
                  <geometry>
					<sphere>
						<radius>0.1</radius>
					</sphere>			
          		  </geometry>
              </collision>
        	  <visual name="1area_ball_visual">
          		<geometry>
					<sphere>
						<radius>0.1</radius>
					</sphere>			
          		</geometry>
          		<material>
        			<ambient>0.43 0.74 0.93 1</ambient>
        			<diffuse>0.43 0.74 0.93 1</diffuse>
      			</material>
              </visual>
           </link>

			<joint name="1area_ball2_2_joint" type="ball">
				<pose>0 0 0.3 0 0 0</pose>
				<parent>base_link</parent>
				<child>1area_ball2_2</child>
				<dynamics>
        			<damping>0.5</damping> 
      			</dynamics>
    		</joint>

			<link name='1area_ball2_3'>
			  <pose> 2 2.18 0.3 0 0 0</pose>
           	  <collision name="1area_ball_collision">
                  <geometry>
					<sphere>
						<radius>0.1</radius>
					</sphere>			
          		  </geometry>
              </collision>
        	  <visual name="1area_ball_visual">
          		<geometry>
					<sphere>
						<radius>0.1</radius>
					</sphere>			
          		</geometry>
          		<material>
					<ambient>0.92 0.45 0.17 1</ambient>
        			<diffuse>0.92 0.45 0.17 1</diffuse>
      			</material>
              </visual>
           </link>

			<joint name="1area_ball2_3_joint" type="ball">
				<pose>0 0 0.3 0 0 0</pose>
				<parent>base_link</parent>
				<child>1area_ball2_3</child>
				<dynamics>
        			<damping>0.5</damping> 
      			</dynamics>
    		</joint>

			<link name='1area_ball2_4'>
			  <pose> 3.2 2.18 0.3 0 0 0</pose>
           	  <collision name="1area_ball_collision">
                  <geometry>
					<sphere>
						<radius>0.1</radius>
					</sphere>			
          		  </geometry>
              </collision>
        	  <visual name="1area_ball_visual">
          		<geometry>
					<sphere>
						<radius>0.1</radius>
					</sphere>			
          		</geometry>
          		<material>
        			<ambient>0.43 0.74 0.93 1</ambient>
        			<diffuse>0.43 0.74 0.93 1</diffuse>
      			</material>
              </visual>
           </link>

			<joint name="1area_ball2_4_joint" type="ball">
				<pose>0 0 0.3 0 0 0</pose>
				<parent>base_link</parent>
				<child>1area_ball2_4</child>
				<dynamics>
        			<damping>0.5</damping> 
      			</dynamics>
    		</joint>

			<link name='1area_ball3_1'>
			  <pose> -0.4 3.02 0.3 0 0 0</pose>
           	  <collision name="1area_ball_collision">
                  <geometry>
					<sphere>
						<radius>0.1</radius>
					</sphere>			
          		  </geometry>
              </collision>
        	  <visual name="1area_ball_visual">
          		<geometry>
					<sphere>
						<radius>0.1</radius>
					</sphere>			
          		</geometry>
          		<material>
        			<ambient>0.43 0.74 0.93 1</ambient>
        			<diffuse>0.43 0.74 0.93 1</diffuse>
      			</material>
              </visual>
           </link>

			<joint name="1area_ball3_1_joint" type="ball">
				<pose>0 0 0.3 0 0 0</pose>
				<parent>base_link</parent>
				<child>1area_ball3_1</child>
				<dynamics>
        			<damping>0.5</damping> 
      			</dynamics>
    		</joint>

			<link name='1area_ball3_2'>
			  <pose> 0.8 3.02 0.3 0 0 0</pose>
           	  <collision name="1area_ball_collision">
                  <geometry>
					<sphere>
						<radius>0.1</radius>
					</sphere>			
          		  </geometry>
              </collision>
        	  <visual name="1area_ball_visual">
          		<geometry>
					<sphere>
						<radius>0.1</radius>
					</sphere>			
          		</geometry>
          		<material>
        			<ambient>0.43 0.74 0.93 1</ambient>
        			<diffuse>0.43 0.74 0.93 1</diffuse>
      			</material>
              </visual>
           </link>

			<joint name="1area_ball3_2_joint" type="ball">
				<pose>0 0 0.3 0 0 0</pose>
				<parent>base_link</parent>
				<child>1area_ball3_2</child>
				<dynamics>
        			<damping>0.5</damping> 
      			</dynamics>
    		</joint>

			<link name='1area_ball3_3'>
			  <pose> 2 3.02 0.3 0 0 0</pose>
           	  <collision name="1area_ball_collision">
                  <geometry>
					<sphere>
						<radius>0.1</radius>
					</sphere>			
          		  </geometry>
              </collision>
        	  <visual name="1area_ball_visual">
          		<geometry>
					<sphere>
						<radius>0.1</radius>
					</sphere>			
          		</geometry>
          		<material>
        			<ambient>0.43 0.74 0.93 1</ambient>
        			<diffuse>0.43 0.74 0.93 1</diffuse>
      			</material>
              </visual>
           </link>

			<joint name="1area_ball3_3_joint" type="ball">
				<pose>0 0 0.3 0 0 0</pose>
				<parent>base_link</parent>
				<child>1area_ball3_3</child>
				<dynamics>
        			<damping>0.5</damping> 
      			</dynamics>
    		</joint>

			<link name='1area_ball3_4'>
			  <pose> 3.2 3.02 0.3 0 0 0</pose>
           	  <collision name="1area_ball_collision">
                  <geometry>
					<sphere>
						<radius>0.1</radius>
					</sphere>			
          		  </geometry>
              </collision>
        	  <visual name="1area_ball_visual">
          		<geometry>
					<sphere>
						<radius>0.1</radius>
					</sphere>			
          		</geometry>
          		<material>
        			<ambient>0.92 0.45 0.17 1</ambient>
        			<diffuse>0.92 0.45 0.17 1</diffuse>
      			</material>
              </visual>
           </link>

			<joint name="1area_ball3_4_joint" type="ball">
				<pose>0 0 0.3 0 0 0</pose>
				<parent>base_link</parent>
				<child>1area_ball3_4</child>
				<dynamics>
        			<damping>0.5</damping> 
      			</dynamics>
    		</joint>
			
		</model>

		<model name="hanging_ball2">
			<link name="base_link2"></link>
			
			<joint name="world_to_base2" type="fixed">
      			<parent>world</parent>
      			<child>base_link2</child>
      			<pose>0 0 0 0 0 0</pose> 
    		</joint>

			<link name='1area_ball4_1'>
			  <pose> -0.4 3.86 0.3 0 0 0</pose>
           	  <collision name="1area_ball_collision">
                  <geometry>
					<sphere>
						<radius>0.1</radius>
					</sphere>			
          		  </geometry>
              </collision>
        	  <visual name="1area_ball_visual">
          		<geometry>
					<sphere>
						<radius>0.1</radius>
					</sphere>			
          		</geometry>
          		<material>
        			<ambient>0.92 0.45 0.17 1</ambient>
        			<diffuse>0.92 0.45 0.17 1</diffuse>
      			</material>
              </visual>
           </link>

			<joint name="1area_ball4_1_joint" type="ball">
				<pose>0 0 0.3 0 0 0</pose>
				<parent>base_link2</parent>
				<child>1area_ball4_1</child>
				<dynamics>
        			<damping>0.5</damping> 
      			</dynamics>
    		</joint>

			<link name='1area_ball4_2'>
			  <pose> 0.8 3.86 0.3 0 0 0</pose>
           	  <collision name="1area_ball_collision">
                  <geometry>
					<sphere>
						<radius>0.1</radius>
					</sphere>			
          		  </geometry>
              </collision>
        	  <visual name="1area_ball_visual">
          		<geometry>
					<sphere>
						<radius>0.1</radius>
					</sphere>			
          		</geometry>
          		<material>
        			<ambient>0.43 0.74 0.93 1</ambient>
        			<diffuse>0.43 0.74 0.93 1</diffuse>
      			</material>
              </visual>
           </link>

			<joint name="1area_ball4_2_joint" type="ball">
				<pose>0 0 0.3 0 0 0</pose>
				<parent>base_link2</parent>
				<child>1area_ball4_2</child>
				<dynamics>
        			<damping>0.5</damping> 
      			</dynamics>
    		</joint>

			<link name='1area_ball4_3'>
			  <pose> 2 3.86 0.3 0 0 0</pose>
           	  <collision name="1area_ball_collision">
                  <geometry>
					<sphere>
						<radius>0.1</radius>
					</sphere>			
          		  </geometry>
              </collision>
        	  <visual name="1area_ball_visual">
          		<geometry>
					<sphere>
						<radius>0.1</radius>
					</sphere>			
          		</geometry>
          		<material>
        			<ambient>0.43 0.74 0.93 1</ambient>
        			<diffuse>0.43 0.74 0.93 1</diffuse>
      			</material>
              </visual>
           </link>

			<joint name="1area_ball4_3_joint" type="ball">
				<pose>0 0 0.3 0 0 0</pose>
				<parent>base_link2</parent>
				<child>1area_ball4_3</child>
				<dynamics>
        			<damping>0.5</damping> 
      			</dynamics>
    		</joint>

			<link name='1area_ball4_4'>
			  <pose> 3.2 3.86 0.3 0 0 0</pose>
           	  <collision name="1area_ball_collision">
                  <geometry>
					<sphere>
						<radius>0.1</radius>
					</sphere>			
          		  </geometry>
              </collision>
        	  <visual name="1area_ball_visual">
          		<geometry>
					<sphere>
						<radius>0.1</radius>
					</sphere>			
          		</geometry>
          		<material>
        			<ambient>0.43 0.74 0.93 1</ambient>
        			<diffuse>0.43 0.74 0.93 1</diffuse>
      			</material>
              </visual>
           </link>

			<joint name="1area_ball4_4_joint" type="ball">
				<pose>0 0 0.3 0 0 0</pose>
				<parent>base_link2</parent>
				<child>1area_ball4_4</child>
				<dynamics>
        			<damping>0.5</damping> 
      			</dynamics>
    		</joint>
		</model>	
		
    </world>
</sdf>
